2025-09-15 22:35:24,657 - __main__ - INFO - log_function_entry:54 - [ENTER] main()
2025-09-15 22:35:24,657 - __main__ - INFO - main:103 - Starting logging functionality test
2025-09-15 22:35:24,657 - __main__ - INFO - main:106 - Testing successful function execution...
2025-09-15 22:35:24,657 - __main__ - INFO - log_function_entry:54 - [ENTER] test_function(param1=value1, param2=42)
2025-09-15 22:35:24,657 - __main__ - INFO - test_function:70 - Performing some test operations...
2025-09-15 22:35:24,657 - __main__ - INFO - test_function:74 - Processing step 1/3
2025-09-15 22:35:24,657 - __main__ - INFO - test_function:74 - Processing step 2/3
2025-09-15 22:35:24,657 - __main__ - INFO - test_function:74 - Processing step 3/3
2025-09-15 22:35:24,657 - __main__ - INFO - log_function_exit:59 - [EXIT] test_function - SUCCESS All operations completed
2025-09-15 22:35:24,657 - __main__ - INFO - main:110 - Testing function with error handling...
2025-09-15 22:35:24,657 - __main__ - INFO - log_function_entry:54 - [ENTER] test_function_with_error()
2025-09-15 22:35:24,657 - __main__ - INFO - test_function_with_error:90 - About to trigger an error...
2025-09-15 22:35:24,657 - __main__ - ERROR - log_function_error:63 - [ERROR] test_function_with_error: This is a test error
Traceback (most recent call last):
  File "D:\_Dev\python\pais_results - Copy\test_logging.py", line 91, in test_function_with_error
    raise ValueError("This is a test error")
ValueError: This is a test error
2025-09-15 22:35:24,657 - __main__ - INFO - log_function_exit:59 - [EXIT] test_function_with_error - FAILED Failed as expected: This is a test error
2025-09-15 22:35:24,657 - __main__ - INFO - main:113 - Logging test completed successfully!
2025-09-15 22:35:24,657 - __main__ - INFO - log_function_exit:59 - [EXIT] main - SUCCESS All logging tests passed
